{"timestamp": "2025-07-08T17:52:13.129372", "level": "ERROR", "logger": "Hearthlink", "message": "Error in test_error_context: Test error for logging", "module": "main", "function": "log_error", "line": 309, "exception": {"type": "ValueError", "message": "Test error for logging", "traceback": ["Traceback (most recent call last):\n", "  File \"G:\\MythologIQ\\Hearthlink\\tests\\test_logging.py\", line 75, in test_structured_logging\n    raise ValueError(\"Test error for logging\")\n", "ValueError: Test error for logging\n"]}, "event_type": "error", "error_type": "ValueError", "error_message": "Test error for logging", "context": "test_error_context", "traceback": ["Traceback (most recent call last):\n", "  File \"G:\\MythologIQ\\Hearthlink\\tests\\test_logging.py\", line 75, in test_structured_logging\n    raise ValueError(\"Test error for logging\")\n", "ValueError: Test error for logging\n"], "test_id": "003", "expected": true}
